Step #0.00 (0ms ?*RT. ?UPS, TraCI: 30ms, vehicles TOT 0 ACT 0 BUF 0)                     
Interrupt signal received, trying to exit gracefully.
Traceback (most recent call last):
  File "/Users/amirhosseinkiani/Documents/Github/FRITS-Backup/.venv/lib/python3.10/site-packages/traci/main.py", line 97, in connect
    return connection.Connection(host, port, proc, traceFile, traceGetters, label)
  File "/Users/amirhosseinkiani/Documents/Github/FRITS-Backup/.venv/lib/python3.10/site-packages/traci/connection.py", line 83, in __init__
    self._socket.connect((host, port))
ConnectionRefusedError: [Errno 61] Connection refused

During handling of the above exception, another exception occurred:

Traceback (most recent call last):
  File "/opt/homebrew/Cellar/python@3.10/3.10.17/Frameworks/Python.framework/Versions/3.10/lib/python3.10/runpy.py", line 196, in _run_module_as_main
    return _run_code(code, main_globals, None,
  File "/opt/homebrew/Cellar/python@3.10/3.10.17/Frameworks/Python.framework/Versions/3.10/lib/python3.10/runpy.py", line 86, in _run_code
    exec(code, run_globals)
  File "/Users/amirhosseinkiani/Documents/Github/FRITS-Backup/src/models/fedlight/main.py", line 245, in <module>
    main()
  File "/Users/amirhosseinkiani/Documents/Github/FRITS-Backup/src/models/fedlight/main.py", line 71, in main
    env.reset()
  File "/Users/amirhosseinkiani/Documents/Github/FRITS-Backup/src/models/fedlight/enviroment/custom_sumorl_env.py", line 289, in reset
    super().reset(seed=seed, **kwargs)
  File "/Users/amirhosseinkiani/Documents/Github/FRITS-Backup/.venv/lib/python3.10/site-packages/sumo_rl/environment/env.py", line 255, in reset
    self._start_simulation()
  File "/Users/amirhosseinkiani/Documents/Github/FRITS-Backup/.venv/lib/python3.10/site-packages/sumo_rl/environment/env.py", line 235, in _start_simulation
    traci.start(sumo_cmd, label=self.label)
  File "/Users/amirhosseinkiani/Documents/Github/FRITS-Backup/.venv/lib/python3.10/site-packages/traci/main.py", line 147, in start
    result = init(sumoPort, numRetries, "localhost", label, sumoProcess, doSwitch, traceFile, traceGetters)
  File "/Users/amirhosseinkiani/Documents/Github/FRITS-Backup/.venv/lib/python3.10/site-packages/traci/main.py", line 116, in init
    con = connect(port, numRetries, host, proc, 1, traceFile, traceGetters, label)
  File "/Users/amirhosseinkiani/Documents/Github/FRITS-Backup/.venv/lib/python3.10/site-packages/traci/main.py", line 105, in connect
    time.sleep(waitBetweenRetries)
KeyboardInterrupt
 Retrying in 1 seconds
 Retrying in 1 seconds
Simulation completed and TraCI closed.
